<?xml version="1.0" encoding="utf-8"?>
<!-- =================================================================================== -->
<!-- |    This document was autogenerated by xacro from test.urdf.xacro                | -->
<!-- |    EDITING THIS FILE BY HAND IS NOT RECOMMENDED                                 | -->
<!-- =================================================================================== -->
<robot name="onrobot_rg_test">
  <material name="onrobot/grey">
    <color rgba="0.65 0.62 0.58 1.0"/>
  </material>
  <material name="onrobot/light_grey">
    <color rgba="0.9 0.92 0.93 1.0"/>
  </material>
  <material name="onrobot/dark_grey">
    <color rgba="0.25 0.25 0.25 1.0"/>
  </material>
  <link name="world"/>
  <!-- bracket -->
  <link name="rg2_bracket">
    <visual>
      <geometry>
        <mesh filename="package://onrobot_description/meshes/rg2_v1/visual/single_bracket.stl"/>
      </geometry>
      <material name="onrobot/grey"/>
    </visual>
    <collision>
      <geometry>
        <mesh filename="package://onrobot_description/meshes/rg2_v1/collision/single_bracket.stl"/>
      </geometry>
    </collision>
    <inertial>
      <mass value="0.09"/>
      <inertia ixx="0.001" ixy="0.0" ixz="0.0" iyy="0.001" iyz="0.0" izz="0.001"/>
    </inertial>
  </link>
  <joint name="rg2_bracket_joint" type="fixed">
    <parent link="world"/>
    <child link="rg2_bracket"/>
    <origin rpy="0.0 0.0 0.0" xyz="0.0 0.05 0.0"/>
  </joint>
  <!-- body -->
  <link name="rg2_body">
    <visual>
      <geometry>
        <mesh filename="package://onrobot_description/meshes/rg2_v1/visual/body.stl"/>
      </geometry>
      <material name="onrobot/light_grey"/>
    </visual>
    <collision>
      <geometry>
        <mesh filename="package://onrobot_description/meshes/rg2_v1/collision/body.stl"/>
      </geometry>
    </collision>
    <inertial>
      <mass value="0.65"/>
      <inertia ixx="0.001" ixy="0.0" ixz="0.0" iyy="0.001" iyz="0.0" izz="0.001"/>
    </inertial>
  </link>
  <joint name="rg2_body_joint" type="fixed">
    <parent link="rg2_bracket"/>
    <child link="rg2_body"/>
    <origin rpy="0.0 0.0 0.0" xyz="0.0 0.0 0.05"/>
  </joint>
  <!-- grasp frame -->
  <link name="rg2_grasp_frame"/>
  <joint name="rg2_grasp_frame_joint" type="fixed">
    <parent link="rg2_body"/>
    <child link="rg2_grasp_frame"/>
    <origin rpy="0.0 0.0 0.0" xyz="0.0 0.0 0.14"/>
  </joint>
  <!-- origin frame -->
  <link name="rg2_finger_1_origin">
    <inertial>
      <mass value="0.001"/>
      <inertia ixx="0.00001" ixy="0.0" ixz="0.0" iyy="0.00001" iyz="0.0" izz="0.00001"/>
    </inertial>
  </link>
  <joint name="rg2_finger_1_origin_joint" type="fixed">
    <parent link="rg2_body"/>
    <child link="rg2_finger_1_origin"/>
    <origin rpy="0 0 0" xyz="0 0 0"/>
  </joint>
  <!-- moment bar -->
  <link name="rg2_finger_1_moment_arm">
    <visual>
      <geometry>
        <mesh filename="package://onrobot_description/meshes/rg2_v1/visual/moment_arm.stl"/>
      </geometry>
      <material name="onrobot/light_grey"/>
    </visual>
    <collision>
      <geometry>
        <mesh filename="package://onrobot_description/meshes/rg2_v1/collision/moment_arm.stl"/>
      </geometry>
    </collision>
    <inertial>
      <mass value="0.001"/>
      <inertia ixx="0.001" ixy="0.0" ixz="0.0" iyy="0.001" iyz="0.0" izz="0.001"/>
    </inertial>
  </link>
  <joint name="rg2_joint" type="revolute">
    <parent link="rg2_finger_1_origin"/>
    <child link="rg2_finger_1_moment_arm"/>
    <axis xyz="0 1 0"/>
    <origin rpy="0.0 -0.772 0.0" xyz="-0.017 0.0 0.055"/>
    <limit effort="2.2" lower="0.0" upper="1.3" velocity="0.5"/>
    <dynamics damping="0.5"/>
  </joint>
  <!-- truss bar -->
  <link name="rg2_finger_1_truss_arm">
    <visual>
      <geometry>
        <mesh filename="package://onrobot_description/meshes/rg2_v1/visual/truss_arm.stl"/>
      </geometry>
      <material name="onrobot/light_grey"/>
    </visual>
    <collision>
      <geometry>
        <mesh filename="package://onrobot_description/meshes/rg2_v1/collision/truss_arm.stl"/>
      </geometry>
    </collision>
    <inertial>
      <mass value="0.001"/>
      <inertia ixx="0.001" ixy="0.0" ixz="0.0" iyy="0.001" iyz="0.0" izz="0.001"/>
    </inertial>
  </link>
  <joint name="rg2_finger_1_truss_arm_joint" type="revolute">
    <parent link="rg2_finger_1_origin"/>
    <child link="rg2_finger_1_truss_arm"/>
    <axis xyz="0 1 0"/>
    <origin rpy="0.0 -0.772 0.0" xyz="-0.0075 0.0 0.0715"/>
    <limit effort="2.2" lower="0.0" upper="1.3" velocity="0.5"/>
    <mimic joint="rg2_joint" multiplier="1" offset="0"/>
  </joint>
  <!-- finger tip -->
  <link name="rg2_finger_1_finger_tip">
    <visual>
      <geometry>
        <mesh filename="package://onrobot_description/meshes/rg2_v1/visual/finger_tip.stl"/>
      </geometry>
      <material name="onrobot/light_grey"/>
    </visual>
    <collision>
      <geometry>
        <mesh filename="package://onrobot_description/meshes/rg2_v1/collision/finger_tip_1.stl"/>
      </geometry>
    </collision>
    <collision>
      <geometry>
        <mesh filename="package://onrobot_description/meshes/rg2_v1/collision/finger_tip_2.stl"/>
      </geometry>
    </collision>
    <inertial>
      <mass value="0.001"/>
      <inertia ixx="0.001" ixy="0.0" ixz="0.0" iyy="0.001" iyz="0.0" izz="0.001"/>
    </inertial>
  </link>
  <joint name="rg2_finger_1_finger_tip_joint" type="revolute">
    <parent link="rg2_finger_1_truss_arm"/>
    <child link="rg2_finger_1_finger_tip"/>
    <axis xyz="0 -1 0"/>
    <origin rpy="0.0 0.772 0.0" xyz="-0.0256 0.0 0.04868"/>
    <limit effort="2.2" lower="0.0" upper="1.3" velocity="0.5"/>
    <mimic joint="rg2_joint" multiplier="1" offset="0"/>
  </joint>
  <!-- flex finger -->
  <link name="rg2_finger_1_flex_finger">
    <visual>
      <geometry>
        <mesh filename="package://onrobot_description/meshes/rg2_v1/visual/flex_finger.stl"/>
      </geometry>
      <material name="onrobot/dark_grey"/>
    </visual>
    <collision>
      <geometry>
        <mesh filename="package://onrobot_description/meshes/rg2_v1/collision/flex_finger.stl"/>
      </geometry>
    </collision>
    <inertial>
      <mass value="0.001"/>
      <inertia ixx="0.001" ixy="0.0" ixz="0.0" iyy="0.001" iyz="0.0" izz="0.001"/>
    </inertial>
  </link>
  <joint name="rg2_finger_1_flex_finger_joint" type="fixed">
    <parent link="rg2_finger_1_finger_tip"/>
    <child link="rg2_finger_1_flex_finger"/>
    <origin rpy="0.0 0.0 0.0" xyz="0.03059 0.0 0.0172"/>
  </joint>
  <!-- origin frame -->
  <link name="rg2_finger_2_origin">
    <inertial>
      <mass value="0.001"/>
      <inertia ixx="0.00001" ixy="0.0" ixz="0.0" iyy="0.00001" iyz="0.0" izz="0.00001"/>
    </inertial>
  </link>
  <joint name="rg2_finger_2_origin_joint" type="fixed">
    <parent link="rg2_body"/>
    <child link="rg2_finger_2_origin"/>
    <origin rpy="0 0 3.14159265359" xyz="0 0 0"/>
  </joint>
  <!-- moment bar -->
  <link name="rg2_finger_2_moment_arm">
    <visual>
      <geometry>
        <mesh filename="package://onrobot_description/meshes/rg2_v1/visual/moment_arm.stl"/>
      </geometry>
      <material name="onrobot/light_grey"/>
    </visual>
    <collision>
      <geometry>
        <mesh filename="package://onrobot_description/meshes/rg2_v1/collision/moment_arm.stl"/>
      </geometry>
    </collision>
    <inertial>
      <mass value="0.001"/>
      <inertia ixx="0.001" ixy="0.0" ixz="0.0" iyy="0.001" iyz="0.0" izz="0.001"/>
    </inertial>
  </link>
  <joint name="rg2_mirror_joint" type="revolute">
    <parent link="rg2_finger_2_origin"/>
    <child link="rg2_finger_2_moment_arm"/>
    <axis xyz="0 1 0"/>
    <origin rpy="0.0 -0.772 0.0" xyz="-0.017 0.0 0.055"/>
    <limit effort="2.2" lower="0.0" upper="1.3" velocity="0.5"/>
    <dynamics damping="0.5"/>
    <mimic joint="rg2_joint" multiplier="1" offset="0"/>
  </joint>
  <!-- truss bar -->
  <link name="rg2_finger_2_truss_arm">
    <visual>
      <geometry>
        <mesh filename="package://onrobot_description/meshes/rg2_v1/visual/truss_arm.stl"/>
      </geometry>
      <material name="onrobot/light_grey"/>
    </visual>
    <collision>
      <geometry>
        <mesh filename="package://onrobot_description/meshes/rg2_v1/collision/truss_arm.stl"/>
      </geometry>
    </collision>
    <inertial>
      <mass value="0.001"/>
      <inertia ixx="0.001" ixy="0.0" ixz="0.0" iyy="0.001" iyz="0.0" izz="0.001"/>
    </inertial>
  </link>
  <joint name="rg2_finger_2_truss_arm_joint" type="revolute">
    <parent link="rg2_finger_2_origin"/>
    <child link="rg2_finger_2_truss_arm"/>
    <axis xyz="0 1 0"/>
    <origin rpy="0.0 -0.772 0.0" xyz="-0.0075 0.0 0.0715"/>
    <limit effort="2.2" lower="0.0" upper="1.3" velocity="0.5"/>
    <mimic joint="rg2_joint" multiplier="1" offset="0"/>
  </joint>
  <!-- finger tip -->
  <link name="rg2_finger_2_finger_tip">
    <visual>
      <geometry>
        <mesh filename="package://onrobot_description/meshes/rg2_v1/visual/finger_tip.stl"/>
      </geometry>
      <material name="onrobot/light_grey"/>
    </visual>
    <collision>
      <geometry>
        <mesh filename="package://onrobot_description/meshes/rg2_v1/collision/finger_tip_1.stl"/>
      </geometry>
    </collision>
    <collision>
      <geometry>
        <mesh filename="package://onrobot_description/meshes/rg2_v1/collision/finger_tip_2.stl"/>
      </geometry>
    </collision>
    <inertial>
      <mass value="0.001"/>
      <inertia ixx="0.001" ixy="0.0" ixz="0.0" iyy="0.001" iyz="0.0" izz="0.001"/>
    </inertial>
  </link>
  <joint name="rg2_finger_2_finger_tip_joint" type="revolute">
    <parent link="rg2_finger_2_truss_arm"/>
    <child link="rg2_finger_2_finger_tip"/>
    <axis xyz="0 -1 0"/>
    <origin rpy="0.0 0.772 0.0" xyz="-0.0256 0.0 0.04868"/>
    <limit effort="2.2" lower="0.0" upper="1.3" velocity="0.5"/>
    <mimic joint="rg2_joint" multiplier="1" offset="0"/>
  </joint>
  <!-- flex finger -->
  <link name="rg2_finger_2_flex_finger">
    <visual>
      <geometry>
        <mesh filename="package://onrobot_description/meshes/rg2_v1/visual/flex_finger.stl"/>
      </geometry>
      <material name="onrobot/dark_grey"/>
    </visual>
    <collision>
      <geometry>
        <mesh filename="package://onrobot_description/meshes/rg2_v1/collision/flex_finger.stl"/>
      </geometry>
    </collision>
    <inertial>
      <mass value="0.001"/>
      <inertia ixx="0.001" ixy="0.0" ixz="0.0" iyy="0.001" iyz="0.0" izz="0.001"/>
    </inertial>
  </link>
  <joint name="rg2_finger_2_flex_finger_joint" type="fixed">
    <parent link="rg2_finger_2_finger_tip"/>
    <child link="rg2_finger_2_flex_finger"/>
    <origin rpy="0.0 0.0 0.0" xyz="0.03059 0.0 0.0172"/>
  </joint>
  <!-- <transmission name="${prefix}_joint_trans">
      <type>transmission_interface/SimpleTransmission</type>
      <joint name="${prefix}_joint">
        <hardwareInterface>${hw_interface}</hardwareInterface>
      </joint>
      <actuator name="${prefix}_joint_motor">
        <hardwareInterface>${hw_interface}</hardwareInterface>
        <mechanicalReduction>1</mechanicalReduction>
      </actuator>
    </transmission> -->
  <!-- load "onrobot_gripper_plugin" plugin -->
  <gazebo>
    <plugin filename="libonrobot_gripper_plugin.so" name="rg2_plugin">
      <robotNamespace>/rg2</robotNamespace>
      <jointName>rg2_joint, rg2_mirror_joint</jointName>
      <tipName>rg2_finger_1_finger_tip, rg2_finger_2_finger_tip</tipName>
      <palmName>rg2_body</palmName>
      <maxEffort>0.5</maxEffort>
    </plugin>
  </gazebo>
  <gazebo>
    <joint name="rg2_finger_1_close_loop_joint" type="revolute">
      <parent>rg2_finger_1_moment_arm</parent>
      <child>rg2_finger_1_finger_tip</child>
      <pose frame="">-0.0095 0.0 -0.0165 0 0 0</pose>
      <axis>
        <xyz>0 -1 0</xyz>
        <use_parent_model_frame>0</use_parent_model_frame>
      </axis>
    </joint>
    <joint name="rg2_finger_2_close_loop_joint" type="revolute">
      <parent>rg2_finger_2_moment_arm</parent>
      <child>rg2_finger_2_finger_tip</child>
      <pose frame="">-0.0095 0.0 -0.0165 0 0 0</pose>
      <axis>
        <xyz>0 -1 0</xyz>
        <use_parent_model_frame>0</use_parent_model_frame>
      </axis>
    </joint>
  </gazebo>
  <gazebo reference="rg2_finger_1_flex_finger">
    <mu1>100</mu1>
    <mu2>100</mu2>
    <fdir1>0 0 1</fdir1>
    <kp>100000</kp>
    <kd>10</kd>
    <collision name="rg2_finger_1_flex_finger_collision">
      <surface>
        <friction>
          <torsional>
            <coefficient>0.456</coefficient>
            <use_patch_radius>true</use_patch_radius>
            <patch_radius>0.05</patch_radius>
          </torsional>
        </friction>
      </surface>
    </collision>
  </gazebo>
  <gazebo reference="rg2_finger_2_flex_finger">
    <mu1>100</mu1>
    <mu2>100</mu2>
    <fdir1>0 0 1</fdir1>
    <kp>100000</kp>
    <kd>10</kd>
    <collision name="rg2_finger_2_flex_finger_collision">
      <surface>
        <friction>
          <torsional>
            <coefficient>0.456</coefficient>
            <use_patch_radius>true</use_patch_radius>
            <patch_radius>0.05</patch_radius>
          </torsional>
        </friction>
      </surface>
    </collision>
  </gazebo>
  <!-- enable self collision -->
  <gazebo reference="rg2_bracket">
    <selfCollide>true</selfCollide>
  </gazebo>
  <gazebo reference="rg2_body">
    <selfCollide>true</selfCollide>
  </gazebo>
  <gazebo reference="rg2_finger_1_truss_arm">
    <selfCollide>true</selfCollide>
  </gazebo>
  <gazebo reference="rg2_finger_1_moment_arm">
    <selfCollide>true</selfCollide>
  </gazebo>
  <gazebo reference="rg2_finger_1_finger_tip">
    <selfCollide>true</selfCollide>
  </gazebo>
  <gazebo reference="rg2_finger_1_flex_finger">
    <selfCollide>true</selfCollide>
  </gazebo>
  <gazebo reference="rg2_finger_2_truss_arm">
    <selfCollide>true</selfCollide>
  </gazebo>
  <gazebo reference="rg2_finger_2_moment_arm">
    <selfCollide>true</selfCollide>
  </gazebo>
  <gazebo reference="rg2_finger_2_finger_tip">
    <selfCollide>true</selfCollide>
  </gazebo>
  <gazebo reference="rg2_finger_2_flex_finger">
    <selfCollide>true</selfCollide>
  </gazebo>
  <!-- bracket -->
  <link name="rg6_bracket">
    <visual>
      <geometry>
        <mesh filename="package://onrobot_description/meshes/rg6_v1/visual/single_bracket.stl"/>
      </geometry>
      <material name="onrobot/grey"/>
    </visual>
    <collision>
      <geometry>
        <mesh filename="package://onrobot_description/meshes/rg6_v1/collision/single_bracket.stl"/>
      </geometry>
    </collision>
    <inertial>
      <mass value="0.001"/>
      <inertia ixx="0.001" ixy="0.0" ixz="0.0" iyy="0.001" iyz="0.0" izz="0.001"/>
    </inertial>
  </link>
  <joint name="rg6_bracket_joint" type="fixed">
    <parent link="world"/>
    <child link="rg6_bracket"/>
    <origin rpy="0.0 0.0 0.0" xyz="0.0 -0.05 0.0"/>
  </joint>
  <!-- body -->
  <link name="rg6_body">
    <visual>
      <geometry>
        <mesh filename="package://onrobot_description/meshes/rg6_v1/visual/body.stl"/>
      </geometry>
      <material name="onrobot/light_grey"/>
    </visual>
    <collision>
      <geometry>
        <mesh filename="package://onrobot_description/meshes/rg6_v1/collision/body.stl"/>
      </geometry>
    </collision>
    <inertial>
      <mass value="0.78"/>
      <inertia ixx="0.001" ixy="0.0" ixz="0.0" iyy="0.001" iyz="0.0" izz="0.001"/>
    </inertial>
  </link>
  <joint name="rg6_body_joint" type="fixed">
    <parent link="rg6_bracket"/>
    <child link="rg6_body"/>
    <origin rpy="0.0 0.0 0.0" xyz="0.0 0.0 0.051"/>
  </joint>
  <!-- grasp frame -->
  <link name="rg6_grasp_frame"/>
  <joint name="rg6_grasp_frame_joint" type="fixed">
    <parent link="rg6_body"/>
    <child link="rg6_grasp_frame"/>
    <origin rpy="0.0 0.0 0.0" xyz="0.0 0.0 0.19"/>
  </joint>
  <!-- origin frame -->
  <link name="rg6_finger_1_origin">
    <inertial>
      <mass value="0.001"/>
      <inertia ixx="0.00001" ixy="0.0" ixz="0.0" iyy="0.00001" iyz="0.0" izz="0.00001"/>
    </inertial>
  </link>
  <joint name="rg6_finger_1_origin_joint" type="fixed">
    <parent link="rg6_body"/>
    <child link="rg6_finger_1_origin"/>
    <origin rpy="0 0 0" xyz="0 0 0"/>
  </joint>
  <!-- moment bar -->
  <link name="rg6_finger_1_moment_arm">
    <visual>
      <geometry>
        <mesh filename="package://onrobot_description/meshes/rg6_v1/visual/moment_arm.stl"/>
      </geometry>
      <material name="onrobot/light_grey"/>
    </visual>
    <collision>
      <geometry>
        <mesh filename="package://onrobot_description/meshes/rg6_v1/collision/moment_arm.stl"/>
      </geometry>
    </collision>
    <inertial>
      <mass value="0.001"/>
      <inertia ixx="0.001" ixy="0.0" ixz="0.0" iyy="0.001" iyz="0.0" izz="0.001"/>
    </inertial>
  </link>
  <joint name="rg6_joint" type="revolute">
    <parent link="rg6_finger_1_origin"/>
    <child link="rg6_finger_1_moment_arm"/>
    <axis xyz="0 1 0"/>
    <origin rpy="0.0 -0.49 0.0" xyz="-0.0238 0.0 0.066"/>
    <limit effort="10.0" lower="0.0" upper="1.3" velocity="2.4"/>
    <dynamics damping="0.5"/>
  </joint>
  <!-- truss bar -->
  <link name="rg6_finger_1_truss_arm">
    <visual>
      <geometry>
        <mesh filename="package://onrobot_description/meshes/rg6_v1/visual/truss_arm.stl"/>
      </geometry>
      <material name="onrobot/light_grey"/>
    </visual>
    <collision>
      <geometry>
        <mesh filename="package://onrobot_description/meshes/rg6_v1/collision/truss_arm.stl"/>
      </geometry>
    </collision>
    <inertial>
      <mass value="0.001"/>
      <inertia ixx="0.001" ixy="0.0" ixz="0.0" iyy="0.001" iyz="0.0" izz="0.001"/>
    </inertial>
  </link>
  <joint name="rg6_finger_1_truss_arm_joint" type="revolute">
    <parent link="rg6_finger_1_origin"/>
    <child link="rg6_finger_1_truss_arm"/>
    <axis xyz="0 1 0"/>
    <origin rpy="0.0 -0.49 0.0" xyz="-0.0105 0.0 0.0891"/>
    <limit effort="10.0" lower="0.0" upper="1.3" velocity="2.4"/>
    <mimic joint="rg6_joint" multiplier="1" offset="0"/>
  </joint>
  <link name="rg6_finger_1_safety_shield">
    <visual>
      <geometry>
        <mesh filename="package://onrobot_description/meshes/rg6_v1/visual/safety_shield.stl"/>
      </geometry>
      <material name="onrobot/dark_grey"/>
    </visual>
    <collision>
      <geometry>
        <!-- <mesh filename="package://onrobot_description/meshes/${model}/collision/safety_shield.stl"/> -->
        <box size="0.0 0.0 0.0"/>
      </geometry>
    </collision>
    <inertial>
      <mass value="0.001"/>
      <inertia ixx="0.001" ixy="0.0" ixz="0.0" iyy="0.001" iyz="0.0" izz="0.001"/>
    </inertial>
  </link>
  <joint name="rg6_finger_1_safety_shield_joint" type="revolute">
    <parent link="rg6_finger_1_finger_tip"/>
    <child link="rg6_finger_1_safety_shield"/>
    <axis xyz="0 1 0"/>
    <origin rpy="0.0 -0.49 0.0" xyz="-0.00665 0.0 -0.01155"/>
    <limit effort="10.0" lower="0.0" upper="1.3" velocity="2.4"/>
    <mimic joint="rg6_joint" multiplier="1" offset="0"/>
  </joint>
  <!-- finger tip -->
  <link name="rg6_finger_1_finger_tip">
    <visual>
      <geometry>
        <mesh filename="package://onrobot_description/meshes/rg6_v1/visual/finger_tip.stl"/>
      </geometry>
      <material name="onrobot/light_grey"/>
    </visual>
    <collision>
      <geometry>
        <mesh filename="package://onrobot_description/meshes/rg6_v1/collision/finger_tip_1.stl"/>
      </geometry>
    </collision>
    <collision>
      <geometry>
        <mesh filename="package://onrobot_description/meshes/rg6_v1/collision/finger_tip_2.stl"/>
      </geometry>
    </collision>
    <inertial>
      <mass value="0.001"/>
      <inertia ixx="0.001" ixy="0.0" ixz="0.0" iyy="0.001" iyz="0.0" izz="0.001"/>
    </inertial>
  </link>
  <joint name="rg6_finger_1_finger_tip_joint" type="revolute">
    <parent link="rg6_finger_1_truss_arm"/>
    <child link="rg6_finger_1_finger_tip"/>
    <axis xyz="0 -1 0"/>
    <origin rpy="0.0 0.49 0.0" xyz="-0.05503 0.0 0.05807"/>
    <limit effort="10.0" lower="0.0" upper="1.3" velocity="2.4"/>
    <mimic joint="rg6_joint" multiplier="1" offset="0"/>
  </joint>
  <!-- flex finger -->
  <link name="rg6_finger_1_flex_finger">
    <visual>
      <geometry>
        <mesh filename="package://onrobot_description/meshes/rg6_v1/visual/flex_finger.stl"/>
      </geometry>
      <material name="onrobot/dark_grey"/>
    </visual>
    <collision>
      <geometry>
        <mesh filename="package://onrobot_description/meshes/rg6_v1/collision/flex_finger.stl"/>
      </geometry>
    </collision>
    <inertial>
      <mass value="0.001"/>
      <inertia ixx="0.001" ixy="0.0" ixz="0.0" iyy="0.001" iyz="0.0" izz="0.001"/>
    </inertial>
  </link>
  <joint name="rg6_finger_1_flex_finger_joint" type="fixed">
    <parent link="rg6_finger_1_finger_tip"/>
    <child link="rg6_finger_1_flex_finger"/>
    <origin rpy="0.0 0.0 0.0" xyz="0.0098 0.0 0.0218"/>
  </joint>
  <!-- origin frame -->
  <link name="rg6_finger_2_origin">
    <inertial>
      <mass value="0.001"/>
      <inertia ixx="0.00001" ixy="0.0" ixz="0.0" iyy="0.00001" iyz="0.0" izz="0.00001"/>
    </inertial>
  </link>
  <joint name="rg6_finger_2_origin_joint" type="fixed">
    <parent link="rg6_body"/>
    <child link="rg6_finger_2_origin"/>
    <origin rpy="0 0 3.14159265359" xyz="0 0 0"/>
  </joint>
  <!-- moment bar -->
  <link name="rg6_finger_2_moment_arm">
    <visual>
      <geometry>
        <mesh filename="package://onrobot_description/meshes/rg6_v1/visual/moment_arm.stl"/>
      </geometry>
      <material name="onrobot/light_grey"/>
    </visual>
    <collision>
      <geometry>
        <mesh filename="package://onrobot_description/meshes/rg6_v1/collision/moment_arm.stl"/>
      </geometry>
    </collision>
    <inertial>
      <mass value="0.001"/>
      <inertia ixx="0.001" ixy="0.0" ixz="0.0" iyy="0.001" iyz="0.0" izz="0.001"/>
    </inertial>
  </link>
  <joint name="rg6_mirror_joint" type="revolute">
    <parent link="rg6_finger_2_origin"/>
    <child link="rg6_finger_2_moment_arm"/>
    <axis xyz="0 1 0"/>
    <origin rpy="0.0 -0.49 0.0" xyz="-0.0238 0.0 0.066"/>
    <limit effort="10.0" lower="0.0" upper="1.3" velocity="2.4"/>
    <dynamics damping="0.5"/>
    <mimic joint="rg6_joint" multiplier="1" offset="0"/>
  </joint>
  <!-- truss bar -->
  <link name="rg6_finger_2_truss_arm">
    <visual>
      <geometry>
        <mesh filename="package://onrobot_description/meshes/rg6_v1/visual/truss_arm.stl"/>
      </geometry>
      <material name="onrobot/light_grey"/>
    </visual>
    <collision>
      <geometry>
        <mesh filename="package://onrobot_description/meshes/rg6_v1/collision/truss_arm.stl"/>
      </geometry>
    </collision>
    <inertial>
      <mass value="0.001"/>
      <inertia ixx="0.001" ixy="0.0" ixz="0.0" iyy="0.001" iyz="0.0" izz="0.001"/>
    </inertial>
  </link>
  <joint name="rg6_finger_2_truss_arm_joint" type="revolute">
    <parent link="rg6_finger_2_origin"/>
    <child link="rg6_finger_2_truss_arm"/>
    <axis xyz="0 1 0"/>
    <origin rpy="0.0 -0.49 0.0" xyz="-0.0105 0.0 0.0891"/>
    <limit effort="10.0" lower="0.0" upper="1.3" velocity="2.4"/>
    <mimic joint="rg6_joint" multiplier="1" offset="0"/>
  </joint>
  <link name="rg6_finger_2_safety_shield">
    <visual>
      <geometry>
        <mesh filename="package://onrobot_description/meshes/rg6_v1/visual/safety_shield.stl"/>
      </geometry>
      <material name="onrobot/dark_grey"/>
    </visual>
    <collision>
      <geometry>
        <!-- <mesh filename="package://onrobot_description/meshes/${model}/collision/safety_shield.stl"/> -->
        <box size="0.0 0.0 0.0"/>
      </geometry>
    </collision>
    <inertial>
      <mass value="0.001"/>
      <inertia ixx="0.001" ixy="0.0" ixz="0.0" iyy="0.001" iyz="0.0" izz="0.001"/>
    </inertial>
  </link>
  <joint name="rg6_finger_2_safety_shield_joint" type="revolute">
    <parent link="rg6_finger_2_finger_tip"/>
    <child link="rg6_finger_2_safety_shield"/>
    <axis xyz="0 1 0"/>
    <origin rpy="0.0 -0.49 0.0" xyz="-0.00665 0.0 -0.01155"/>
    <limit effort="10.0" lower="0.0" upper="1.3" velocity="2.4"/>
    <mimic joint="rg6_joint" multiplier="1" offset="0"/>
  </joint>
  <!-- finger tip -->
  <link name="rg6_finger_2_finger_tip">
    <visual>
      <geometry>
        <mesh filename="package://onrobot_description/meshes/rg6_v1/visual/finger_tip.stl"/>
      </geometry>
      <material name="onrobot/light_grey"/>
    </visual>
    <collision>
      <geometry>
        <mesh filename="package://onrobot_description/meshes/rg6_v1/collision/finger_tip_1.stl"/>
      </geometry>
    </collision>
    <collision>
      <geometry>
        <mesh filename="package://onrobot_description/meshes/rg6_v1/collision/finger_tip_2.stl"/>
      </geometry>
    </collision>
    <inertial>
      <mass value="0.001"/>
      <inertia ixx="0.001" ixy="0.0" ixz="0.0" iyy="0.001" iyz="0.0" izz="0.001"/>
    </inertial>
  </link>
  <joint name="rg6_finger_2_finger_tip_joint" type="revolute">
    <parent link="rg6_finger_2_truss_arm"/>
    <child link="rg6_finger_2_finger_tip"/>
    <axis xyz="0 -1 0"/>
    <origin rpy="0.0 0.49 0.0" xyz="-0.05503 0.0 0.05807"/>
    <limit effort="10.0" lower="0.0" upper="1.3" velocity="2.4"/>
    <mimic joint="rg6_joint" multiplier="1" offset="0"/>
  </joint>
  <!-- flex finger -->
  <link name="rg6_finger_2_flex_finger">
    <visual>
      <geometry>
        <mesh filename="package://onrobot_description/meshes/rg6_v1/visual/flex_finger.stl"/>
      </geometry>
      <material name="onrobot/dark_grey"/>
    </visual>
    <collision>
      <geometry>
        <mesh filename="package://onrobot_description/meshes/rg6_v1/collision/flex_finger.stl"/>
      </geometry>
    </collision>
    <inertial>
      <mass value="0.001"/>
      <inertia ixx="0.001" ixy="0.0" ixz="0.0" iyy="0.001" iyz="0.0" izz="0.001"/>
    </inertial>
  </link>
  <joint name="rg6_finger_2_flex_finger_joint" type="fixed">
    <parent link="rg6_finger_2_finger_tip"/>
    <child link="rg6_finger_2_flex_finger"/>
    <origin rpy="0.0 0.0 0.0" xyz="0.0098 0.0 0.0218"/>
  </joint>
  <!-- <transmission name="${prefix}_joint_trans">
      <type>transmission_interface/SimpleTransmission</type>
      <joint name="${prefix}_joint">
        <hardwareInterface>${hw_interface}</hardwareInterface>
      </joint>
      <actuator name="${prefix}_joint_motor">
        <hardwareInterface>${hw_interface}</hardwareInterface>
        <mechanicalReduction>1</mechanicalReduction>
      </actuator>
    </transmission> -->
  <!-- load "onrobot_gripper_plugin" plugin -->
  <gazebo>
    <plugin filename="libonrobot_gripper_plugin.so" name="rg6_plugin">
      <robotNamespace>/rg6</robotNamespace>
      <jointName>rg6_joint, rg6_mirror_joint</jointName>
      <tipName>rg6_finger_1_finger_tip, rg6_finger_2_finger_tip</tipName>
      <palmName>rg6_body</palmName>
      <mimicName>rg6_finger_1_safety_shield_joint, rg6_finger_2_safety_shield_joint</mimicName>
      <maxEffort>0.5</maxEffort>
    </plugin>
  </gazebo>
  <gazebo>
    <joint name="rg6_finger_1_close_loop_joint" type="revolute">
      <parent>rg6_finger_1_moment_arm</parent>
      <child>rg6_finger_1_finger_tip</child>
      <pose frame="">-0.0133 0.0 -0.0231 0 0 0</pose>
      <axis>
        <xyz>0 -1 0</xyz>
        <use_parent_model_frame>0</use_parent_model_frame>
      </axis>
    </joint>
    <joint name="rg6_finger_2_close_loop_joint" type="revolute">
      <parent>rg6_finger_2_moment_arm</parent>
      <child>rg6_finger_2_finger_tip</child>
      <pose frame="">-0.0133 0.0 -0.0231 0 0 0</pose>
      <axis>
        <xyz>0 -1 0</xyz>
        <use_parent_model_frame>0</use_parent_model_frame>
      </axis>
    </joint>
  </gazebo>
  <gazebo reference="rg6_finger_1_flex_finger">
    <mu1>100</mu1>
    <mu2>100</mu2>
    <fdir1>0 0 1</fdir1>
    <kp>100000</kp>
    <kd>10</kd>
    <collision name="rg6_finger_1_flex_finger_collision">
      <surface>
        <friction>
          <torsional>
            <coefficient>0.456</coefficient>
            <use_patch_radius>true</use_patch_radius>
            <patch_radius>0.05</patch_radius>
          </torsional>
        </friction>
      </surface>
    </collision>
  </gazebo>
  <gazebo reference="rg6_finger_2_flex_finger">
    <mu1>100</mu1>
    <mu2>100</mu2>
    <fdir1>0 0 1</fdir1>
    <kp>100000</kp>
    <kd>10</kd>
    <collision name="rg6_finger_2_flex_finger_collision">
      <surface>
        <friction>
          <torsional>
            <coefficient>0.456</coefficient>
            <use_patch_radius>true</use_patch_radius>
            <patch_radius>0.05</patch_radius>
          </torsional>
        </friction>
      </surface>
    </collision>
  </gazebo>
  <!-- enable self collision -->
  <gazebo reference="rg6_bracket">
    <selfCollide>true</selfCollide>
  </gazebo>
  <gazebo reference="rg6_body">
    <selfCollide>true</selfCollide>
  </gazebo>
  <gazebo reference="rg6_finger_1_truss_arm">
    <selfCollide>true</selfCollide>
  </gazebo>
  <gazebo reference="rg6_finger_1_moment_arm">
    <selfCollide>true</selfCollide>
  </gazebo>
  <gazebo reference="rg6_finger_1_finger_tip">
    <selfCollide>true</selfCollide>
  </gazebo>
  <gazebo reference="rg6_finger_1_flex_finger">
    <selfCollide>true</selfCollide>
  </gazebo>
  <gazebo reference="rg6_finger_2_truss_arm">
    <selfCollide>true</selfCollide>
  </gazebo>
  <gazebo reference="rg6_finger_2_moment_arm">
    <selfCollide>true</selfCollide>
  </gazebo>
  <gazebo reference="rg6_finger_2_finger_tip">
    <selfCollide>true</selfCollide>
  </gazebo>
  <gazebo reference="rg6_finger_2_flex_finger">
    <selfCollide>true</selfCollide>
  </gazebo>
</robot>

